#VRML_SIM R2023a utf8

EXTERNPROTO "https://raw.githubusercontent.com/cyberbotics/webots/R2023a/projects/objects/backgrounds/protos/TexturedBackground.proto"
EXTERNPROTO "https://raw.githubusercontent.com/cyberbotics/webots/R2023a/projects/objects/backgrounds/protos/TexturedBackgroundLight.proto"
EXTERNPROTO "https://raw.githubusercontent.com/cyberbotics/webots/R2023a/projects/objects/floors/protos/Floor.proto"

WorldInfo {
  ERP 0.7
  basicTimeStep 16
  contactProperties [
    ContactProperties {
      material2 "dumbbell"
    }
  ]
}
Viewpoint {
  orientation -0.18122197828326392 -0.09825941708954777 0.9785211707164657 4.117182161232272
  position 2.5310795442070346 3.109858845358103 1.805760017582782
}
TexturedBackground {
}
TexturedBackgroundLight {
}
Floor {
  size 20 20
}
Robot {
  translation 0.4910679159676551 -0.06875867887119219 0.3667123091375083
  rotation 0.003551669234717967 0.9795253948659061 -0.2012893103431921 0.03477196309563725
  children [
    DEF lidar_location Transform {
      translation 0.44 0 0.65
      children [
        Shape {
          appearance Appearance {
            material Material {
              diffuseColor 0.333333 0.341176 0.32549
            }
          }
          geometry Cylinder {
            height 0.08
            radius 0.05
          }
        }
      ]
    }
    Solid {
      translation 0.44 0 0.31
      rotation 0 1 0 0
      children [
        Shape {
          appearance Appearance {
            material Material {
              diffuseColor 0.203922 0.396078 0.643137
            }
          }
          geometry Cylinder {
            height 0.6
            radius 0.02
          }
        }
      ]
      name "lidar beam"
    }
    Transform {
      translation -0.24 -0.4 -0.22
      rotation 0 0 1 1.5707996938995747
      scale 0.28 0.28 0.3
      children [
        DEF RIGHT_REAR_WHEEL_HINGE HingeJoint {
          jointParameters HingeJointParameters {
            position 1.9674109692803115
            dampingConstant 5
            suspensionAxis 0 0 1
          }
          device [
            RotationalMotor {
              name "right_rear_wheel"
              acceleration 2.314814814814815
              maxVelocity 83.33333333333334
              maxTorque 100000000
              sound ""
            }
            PositionSensor {
              name "right_rear_sensor"
            }
            Brake {
              name "right_rear_brake"
            }
          ]
          endPoint Slot {
            type "vehicle wheel"
            endPoint Slot {
              type "vehicle wheel"
              endPoint Solid {
                translation 4.410320372971109e-05 -4.524132167195612e-05 0.0014566409762507729
                rotation 1 0 0 1.2708515406561625e-05
                children [
                  Transform {
                    translation 0.05 0 0
                    rotation 0 1 0 1.5708
                    children [
                      Shape {
                        appearance PBRAppearance {
                          baseColorMap ImageTexture {
                            url [
                              "https://raw.githubusercontent.com/cyberbotics/webots/R2023a/projects/vehicles/protos/generic/textures/tractor_tire_tread_base_color.jpg"
                            ]
                          }
                          roughness 0.4
                          metalness 0
                          normalMap ImageTexture {
                            url [
                              "https://raw.githubusercontent.com/cyberbotics/webots/R2023a/projects/vehicles/protos/generic/textures/tractor_tire_tread_normal.jpg"
                            ]
                          }
                          occlusionMap ImageTexture {
                            url [
                              "https://raw.githubusercontent.com/cyberbotics/webots/R2023a/projects/vehicles/protos/generic/textures/tractor_tire_tread_occlusion.jpg"
                            ]
                          }
                          textureTransform TextureTransform {
                            rotation 1.5708
                            scale 1 7
                          }
                        }
                        geometry Cylinder {
                          bottom FALSE
                          height 0.37
                          radius 0.6
                          top FALSE
                          subdivision 24
                        }
                      }
                      Shape {
                        appearance PBRAppearance {
                          baseColorMap ImageTexture {
                            url [
                              "https://raw.githubusercontent.com/cyberbotics/webots/R2023a/projects/vehicles/protos/generic/textures/tractor_rear_tire_side_base_color.jpg"
                            ]
                          }
                          roughnessMap ImageTexture {
                            url [
                              "https://raw.githubusercontent.com/cyberbotics/webots/R2023a/projects/vehicles/protos/generic/textures/tractor_rear_tire_side_roughness.jpg"
                            ]
                          }
                          metalnessMap ImageTexture {
                            url [
                              "https://raw.githubusercontent.com/cyberbotics/webots/R2023a/projects/vehicles/protos/generic/textures/tractor_rear_tire_side_metalness.jpg"
                            ]
                          }
                          normalMap ImageTexture {
                            url [
                              "https://raw.githubusercontent.com/cyberbotics/webots/R2023a/projects/vehicles/protos/generic/textures/tractor_rear_tire_side_normal.jpg"
                            ]
                          }
                          occlusionMap ImageTexture {
                            url [
                              "https://raw.githubusercontent.com/cyberbotics/webots/R2023a/projects/vehicles/protos/generic/textures/tractor_rear_tire_side_occlusion.jpg"
                            ]
                          }
                        }
                        geometry Cylinder {
                          height 0.37
                          radius 0.6
                          side FALSE
                          subdivision 24
                        }
                      }
                    ]
                  }
                ]
                name "rear right wheel"
                model "tractor rear wheel"
                boundingObject Group {
                  children [
                    Transform {
                      translation 0.04 0 0
                      rotation 0 1 0 1.5708
                      children [
                        Cylinder {
                          height 0.37
                          radius 0.6
                          subdivision 24
                        }
                      ]
                    }
                  ]
                }
                physics Physics {
                  density -1
                  mass 10
                }
                linearVelocity -0.00013961719802540998 3.0072389848865886e-05 -0.0007202527460938836
                angularVelocity 7.763621934918291e-05 -0.00154481461140481 -0.0015559505359034108
              }
            }
          }
        }
      ]
    }
    Transform {
      translation -0.24 0.39 -0.22
      rotation 0 0 1 -1.5708
      scale 0.28 0.28 0.3
      children [
        DEF LEFT_REAR_WHEEL_HINGE HingeJoint {
          jointParameters HingeJointParameters {
            position 8.7411091226374
            axis -1 0 0
            dampingConstant 5
            suspensionAxis 0 0 1
          }
          device [
            RotationalMotor {
              name "left_rear_wheel"
              acceleration 2.314814814814815
              maxVelocity 83.33333333333334
              maxTorque 100000000
              sound ""
            }
            PositionSensor {
              name "left_rear_sensor"
            }
            Brake {
              name "left_rear_brake"
            }
          ]
          endPoint Slot {
            type "vehicle wheel"
            endPoint Slot {
              type "vehicle wheel"
              endPoint Solid {
                translation -4.57173974789699e-05 -0.0003145688459030606 0.0014780422862553035
                rotation 1 0 0 0.0732325057148215
                children [
                  Transform {
                    translation 0.05 0 0
                    rotation 0 -1 0 1.5708
                    children [
                      Shape {
                        appearance PBRAppearance {
                          baseColorMap ImageTexture {
                            url [
                              "https://raw.githubusercontent.com/cyberbotics/webots/R2023a/projects/vehicles/protos/generic/textures/tractor_tire_tread_base_color.jpg"
                            ]
                          }
                          roughness 0.4
                          metalness 0
                          normalMap ImageTexture {
                            url [
                              "https://raw.githubusercontent.com/cyberbotics/webots/R2023a/projects/vehicles/protos/generic/textures/tractor_tire_tread_normal.jpg"
                            ]
                          }
                          occlusionMap ImageTexture {
                            url [
                              "https://raw.githubusercontent.com/cyberbotics/webots/R2023a/projects/vehicles/protos/generic/textures/tractor_tire_tread_occlusion.jpg"
                            ]
                          }
                          textureTransform TextureTransform {
                            rotation 1.5708
                            scale 1 7
                          }
                        }
                        geometry Cylinder {
                          bottom FALSE
                          height 0.37
                          radius 0.6
                          top FALSE
                          subdivision 24
                        }
                      }
                      Shape {
                        appearance PBRAppearance {
                          baseColorMap ImageTexture {
                            url [
                              "https://raw.githubusercontent.com/cyberbotics/webots/R2023a/projects/vehicles/protos/generic/textures/tractor_rear_tire_side_base_color.jpg"
                            ]
                          }
                          roughnessMap ImageTexture {
                            url [
                              "https://raw.githubusercontent.com/cyberbotics/webots/R2023a/projects/vehicles/protos/generic/textures/tractor_rear_tire_side_roughness.jpg"
                            ]
                          }
                          metalnessMap ImageTexture {
                            url [
                              "https://raw.githubusercontent.com/cyberbotics/webots/R2023a/projects/vehicles/protos/generic/textures/tractor_rear_tire_side_metalness.jpg"
                            ]
                          }
                          normalMap ImageTexture {
                            url [
                              "https://raw.githubusercontent.com/cyberbotics/webots/R2023a/projects/vehicles/protos/generic/textures/tractor_rear_tire_side_normal.jpg"
                            ]
                          }
                          occlusionMap ImageTexture {
                            url [
                              "https://raw.githubusercontent.com/cyberbotics/webots/R2023a/projects/vehicles/protos/generic/textures/tractor_rear_tire_side_occlusion.jpg"
                            ]
                          }
                        }
                        geometry Cylinder {
                          height 0.37
                          radius 0.6
                          side FALSE
                          subdivision 24
                        }
                      }
                    ]
                  }
                ]
                name "rear left wheel"
                model "tractor rear wheel"
                boundingObject Group {
                  children [
                    Transform {
                      translation 0.04 0 0
                      rotation 0 1 0 1.5708
                      children [
                        Cylinder {
                          height 0.37
                          radius 0.6
                          subdivision 24
                        }
                      ]
                    }
                  ]
                }
                physics Physics {
                  density -1
                  mass 10
                }
                linearVelocity 0.005732064978099399 -1.1054254678245377e-05 -0.000545039156703513
                angularVelocity 0.00033447255315285717 0.03527933199806469 -0.0015550131423707157
              }
            }
          }
        }
      ]
    }
    Transform {
      translation 0.84 0.37 -0.2
      rotation 0 0 1 -1.5708
      scale 0.38 0.38 0.4
      children [
        DEF LEFT_STEER_HINGE2 Hinge2Joint {
          jointParameters HingeJointParameters {
            position 2.4052076798205482e-06
            axis 0 0 -1
            suspensionAxis 0 0 1
          }
          jointParameters2 JointParameters {
            position 22.954760502993235
            axis -1 0 0
            dampingConstant 5
          }
          device [
            RotationalMotor {
              name "left_steer"
              minPosition -0.45
              maxPosition 0.45
              maxTorque 10000
              sound ""
            }
            PositionSensor {
              name "left_steer_sensor"
            }
          ]
          device2 [
            RotationalMotor {
              name "left_front_wheel"
              acceleration 3.654970760233918
              maxVelocity 131.57894736842104
              maxTorque 0
              sound ""
            }
            PositionSensor {
              name "left_front_sensor"
            }
            Brake {
              name "left_front_brake"
            }
          ]
          endPoint Slot {
            type "vehicle wheel"
            endPoint Slot {
              type "vehicle wheel"
              endPoint Solid {
                translation 2.9801060465469466e-05 -6.2266992645290296e-06 0.0005161489853739672
                rotation 0.9999999999786315 -2.2973862636586453e-06 -6.1203763486981255e-06 0.03522994596172936
                children [
                  Transform {
                    translation 0.041 0 0
                    rotation 0 -1 0 1.5708
                    children [
                      Shape {
                        appearance PBRAppearance {
                          baseColorMap ImageTexture {
                            url [
                              "https://raw.githubusercontent.com/cyberbotics/webots/R2023a/projects/vehicles/protos/generic/textures/tractor_tire_tread_base_color.jpg"
                            ]
                          }
                          roughness 0.4
                          metalness 0
                          normalMap ImageTexture {
                            url [
                              "https://raw.githubusercontent.com/cyberbotics/webots/R2023a/projects/vehicles/protos/generic/textures/tractor_tire_tread_normal.jpg"
                            ]
                          }
                          occlusionMap ImageTexture {
                            url [
                              "https://raw.githubusercontent.com/cyberbotics/webots/R2023a/projects/vehicles/protos/generic/textures/tractor_tire_tread_occlusion.jpg"
                            ]
                          }
                          textureTransform TextureTransform {
                            rotation 1.5708
                            scale 1 7
                          }
                        }
                        geometry Cylinder {
                          bottom FALSE
                          height 0.19
                          radius 0.38
                          top FALSE
                          subdivision 24
                        }
                      }
                      Shape {
                        appearance PBRAppearance {
                          baseColorMap ImageTexture {
                            url [
                              "https://raw.githubusercontent.com/cyberbotics/webots/R2023a/projects/vehicles/protos/generic/textures/tractor_front_tire_side_base_color.jpg"
                            ]
                          }
                          roughnessMap ImageTexture {
                            url [
                              "https://raw.githubusercontent.com/cyberbotics/webots/R2023a/projects/vehicles/protos/generic/textures/tractor_front_tire_side_roughness.jpg"
                            ]
                          }
                          normalMap ImageTexture {
                            url [
                              "https://raw.githubusercontent.com/cyberbotics/webots/R2023a/projects/vehicles/protos/generic/textures/tractor_front_tire_side_normal.jpg"
                            ]
                          }
                          occlusionMap ImageTexture {
                            url [
                              "https://raw.githubusercontent.com/cyberbotics/webots/R2023a/projects/vehicles/protos/generic/textures/tractor_front_tire_side_occlusion.jpg"
                            ]
                          }
                        }
                        geometry Cylinder {
                          height 0.19
                          radius 0.38
                          side FALSE
                          subdivision 24
                        }
                      }
                    ]
                  }
                ]
                name "front left wheel"
                model "tractor front wheel"
                boundingObject Group {
                  children [
                    Transform {
                      translation 0.04 0 0
                      rotation 0 1 0 1.5708
                      children [
                        Cylinder {
                          height 0.19
                          radius 0.38
                          subdivision 24
                        }
                      ]
                    }
                  ]
                }
                physics Physics {
                  density -1
                  mass 10
                }
                linearVelocity 0.003282649814186325 -0.0001189595472340563 0.0009919012039544307
                angularVelocity 0.0004950688478894681 0.022731540365573562 -0.0015889377950035872
              }
            }
          }
        }
      ]
    }
    Transform {
      translation 0.84 -0.38 -0.2
      rotation 0 0 1 1.5708
      scale 0.38 0.38 0.4
      children [
        DEF RIGHT_STEER_HINGE2 Hinge2Joint {
          jointParameters HingeJointParameters {
            position 8.219716805294493e-07
            axis 0 0 -1
            suspensionAxis 0 0 1
          }
          jointParameters2 JointParameters {
            position 20.724316800415718
            axis 1 0 0
            dampingConstant 5
          }
          device [
            RotationalMotor {
              name "right_steer"
              minPosition -0.45
              maxPosition 0.45
              maxTorque 10000
              sound ""
            }
            PositionSensor {
              name "right_steer_sensor"
            }
          ]
          device2 [
            RotationalMotor {
              name "right_front_wheel"
              acceleration 3.654970760233918
              maxVelocity 131.57894736842104
              maxTorque 0
              sound ""
            }
            PositionSensor {
              name "right_front_sensor"
            }
          ]
          endPoint Slot {
            type "vehicle wheel"
            endPoint Slot {
              type "vehicle wheel"
              endPoint Solid {
                translation -2.9628911964653254e-05 1.3234074740528886e-05 0.000497224854765939
                rotation -0.9999999999767356 6.989413671624554e-07 -6.7852974351141735e-06 0.03625982043414559
                children [
                  Transform {
                    translation 0.041 0 0
                    rotation 0 1 0 1.5708
                    children [
                      Shape {
                        appearance PBRAppearance {
                          baseColorMap ImageTexture {
                            url [
                              "https://raw.githubusercontent.com/cyberbotics/webots/R2023a/projects/vehicles/protos/generic/textures/tractor_tire_tread_base_color.jpg"
                            ]
                          }
                          roughness 0.4
                          metalness 0
                          normalMap ImageTexture {
                            url [
                              "https://raw.githubusercontent.com/cyberbotics/webots/R2023a/projects/vehicles/protos/generic/textures/tractor_tire_tread_normal.jpg"
                            ]
                          }
                          occlusionMap ImageTexture {
                            url [
                              "https://raw.githubusercontent.com/cyberbotics/webots/R2023a/projects/vehicles/protos/generic/textures/tractor_tire_tread_occlusion.jpg"
                            ]
                          }
                          textureTransform TextureTransform {
                            rotation 1.5708
                            scale 1 7
                          }
                        }
                        geometry Cylinder {
                          bottom FALSE
                          height 0.19
                          radius 0.38
                          top FALSE
                          subdivision 24
                        }
                      }
                      Shape {
                        appearance PBRAppearance {
                          baseColorMap ImageTexture {
                            url [
                              "https://raw.githubusercontent.com/cyberbotics/webots/R2023a/projects/vehicles/protos/generic/textures/tractor_front_tire_side_base_color.jpg"
                            ]
                          }
                          roughnessMap ImageTexture {
                            url [
                              "https://raw.githubusercontent.com/cyberbotics/webots/R2023a/projects/vehicles/protos/generic/textures/tractor_front_tire_side_roughness.jpg"
                            ]
                          }
                          normalMap ImageTexture {
                            url [
                              "https://raw.githubusercontent.com/cyberbotics/webots/R2023a/projects/vehicles/protos/generic/textures/tractor_front_tire_side_normal.jpg"
                            ]
                          }
                          occlusionMap ImageTexture {
                            url [
                              "https://raw.githubusercontent.com/cyberbotics/webots/R2023a/projects/vehicles/protos/generic/textures/tractor_front_tire_side_occlusion.jpg"
                            ]
                          }
                        }
                        geometry Cylinder {
                          height 0.19
                          radius 0.38
                          side FALSE
                          subdivision 24
                        }
                      }
                    ]
                  }
                ]
                name "front right wheel"
                model "tractor front wheel"
                boundingObject Group {
                  children [
                    Transform {
                      translation 0.04 0 0
                      rotation 0 1 0 1.5708
                      children [
                        Cylinder {
                          height 0.19
                          radius 0.38
                          subdivision 24
                        }
                      ]
                    }
                  ]
                }
                physics Physics {
                  density -1
                  mass 10
                }
                linearVelocity 0.0021355008974310603 -0.00011086651836883775 0.0008356492829985747
                angularVelocity 0.00043884484755663395 0.014788593317136818 -0.00158888274332444
              }
            }
          }
        }
      ]
    }
    Solid {
      translation -0.24 -0.01 -0.42
      scale 0.001 0.001 0.001
      children [
        Shape {
          appearance Appearance {
            material Material {
              diffuseColor 0.933333 0.933333 0.92549
            }
          }
          geometry Mesh {
            url [
              "../stl/eje_trasero.stl"
            ]
          }
        }
      ]
      name "rear axis"
    }
    Solid {
      translation 0.83 -0.015 -0.35
      scale 0.001 0.001 0.001
      children [
        Shape {
          appearance Appearance {
            material Material {
              diffuseColor 0.933333 0.933333 0.92549
            }
          }
          geometry Mesh {
            url [
              "../stl/eje_delantero.stl"
            ]
          }
        }
      ]
      name "frontal axis"
    }
    DEF Body Group {
      children [
        Transform {
          translation 0.5952 -0.002 -0.0782133
          rotation 0 1 0 0.785398
          children [
            Shape {
              appearance Appearance {
                material Material {
                  diffuseColor 0.12549 0.290196 0.529412
                }
              }
              geometry Box {
                size 0.04 0.23 0.23
              }
            }
          ]
        }
        Transform {
          translation 0.128 -0.002 -0.09
          rotation 0 1 0 0
          children [
            Shape {
              appearance Appearance {
                material Material {
                  diffuseColor 0.12549 0.290196 0.529412
                }
              }
              geometry Box {
                size 0.8 0.229 0.17
              }
            }
          ]
        }
        Transform {
          translation 0.656 -0.01 -0.203
          rotation 0 1 0 0
          children [
            Shape {
              appearance Appearance {
                material Material {
                  diffuseColor 0.12549 0.290196 0.529412
                }
              }
              geometry Box {
                size 0.236 0.1 0.12
              }
            }
          ]
        }
        Transform {
          translation 0.831 -0.01 -0.2085
          rotation 0 1 0 0
          children [
            Shape {
              appearance Appearance {
                material Material {
                  diffuseColor 0.12549 0.290196 0.529412
                }
              }
              geometry Box {
                size 0.119 0.5 0.13
              }
            }
          ]
        }
        Transform {
          translation 0.48 0.1873 0
          rotation 0 0 1 -0.7854003061004253
          children [
            Shape {
              appearance Appearance {
                material Material {
                  diffuseColor 0.12549 0.290196 0.529412
                }
              }
              geometry Box {
                size 0.4 0.2 0.02
              }
            }
          ]
        }
        Transform {
          translation 0.48 -0.1885 0
          rotation 0 0 1 0.7853996938995746
          children [
            Shape {
              appearance Appearance {
                material Material {
                  diffuseColor 0.12549 0.290196 0.529412
                }
              }
              geometry Box {
                size 0.4 0.2 0.02
              }
            }
          ]
        }
        Transform {
          translation 0.546 -0.001 0
          rotation 0 0 1 1.5707996938995747
          children [
            Shape {
              appearance Appearance {
                material Material {
                  diffuseColor 0.12549 0.290196 0.529412
                }
              }
              geometry Box {
                size 0.24 0.29 0.02
              }
            }
          ]
        }
        Transform {
          translation -0.307 -0.01 -0.1569
          children [
            Shape {
              appearance Appearance {
                material Material {
                  diffuseColor 0.12549 0.290196 0.529412
                }
              }
              geometry Box {
                size 0.12 0.5 0.29
              }
            }
          ]
        }
        Transform {
          translation -0.25 -0.00999996 -0.22
          rotation 1 0 0 1.5708
          children [
            Shape {
              appearance Appearance {
                material Material {
                  diffuseColor 0.12549 0.290196 0.529412
                }
              }
              geometry Cylinder {
                height 0.5
                radius 0.08
              }
            }
          ]
        }
        Transform {
          translation 0.51 -0.01 -0.17
          rotation 1 0 0 1.5708
          children [
            Shape {
              appearance Appearance {
                material Material {
                  diffuseColor 0.12549 0.290196 0.529412
                }
              }
              geometry Cylinder {
                height 0.1
                radius 0.08
              }
            }
          ]
        }
        Shape {
          appearance Appearance {
            material Material {
              diffuseColor 0.12549 0.290196 0.529412
            }
          }
          geometry Box {
            size 0.82 0.8 0.022
          }
        }
      ]
    }
  ]
  name "Blue"
  model "Aurova"
  boundingObject Group {
    children [
      Shape {
        appearance Appearance {
          material Material {
            diffuseColor 0.12549 0.290196 0.529412
          }
        }
        geometry Box {
          size 0.82 0.8 0.022
        }
      }
      Transform {
        translation 0.51 -0.01 -0.17
        rotation 1 0 0 1.5708
        children [
          Shape {
            appearance Appearance {
              material Material {
                diffuseColor 0.12549 0.290196 0.529412
              }
            }
            geometry Cylinder {
              height 0.1
              radius 0.08
            }
          }
        ]
      }
      Transform {
        translation -0.25 -0.00999996 -0.22
        rotation 1 0 0 1.5708
        children [
          Shape {
            appearance Appearance {
              material Material {
                diffuseColor 0.12549 0.290196 0.529412
              }
            }
            geometry Cylinder {
              height 0.5
              radius 0.08
            }
          }
        ]
      }
      Transform {
        translation -0.307 -0.01 -0.1569
        children [
          Shape {
            appearance Appearance {
              material Material {
                diffuseColor 0.12549 0.290196 0.529412
              }
            }
            geometry Box {
              size 0.12 0.5 0.29
            }
          }
        ]
      }
      Transform {
        translation 0.546 -0.001 0
        rotation 0 0 1 1.5707996938995747
        children [
          Shape {
            appearance Appearance {
              material Material {
                diffuseColor 0.12549 0.290196 0.529412
              }
            }
            geometry Box {
              size 0.24 0.29 0.02
            }
          }
        ]
      }
      Transform {
        translation 0.48 -0.1885 0
        rotation 0 0 1 0.7853996938995746
        children [
          Shape {
            appearance Appearance {
              material Material {
                diffuseColor 0.12549 0.290196 0.529412
              }
            }
            geometry Box {
              size 0.4 0.2 0.02
            }
          }
        ]
      }
      Transform {
        translation 0.48 0.1873 0
        rotation 0 0 1 -0.7854003061004253
        children [
          Shape {
            appearance Appearance {
              material Material {
                diffuseColor 0.12549 0.290196 0.529412
              }
            }
            geometry Box {
              size 0.4 0.2 0.02
            }
          }
        ]
      }
      Transform {
        translation 0.831 -0.01 -0.2085
        rotation 0 1 0 0
        children [
          Shape {
            appearance Appearance {
              material Material {
                diffuseColor 0.12549 0.290196 0.529412
              }
            }
            geometry Box {
              size 0.119 0.5 0.13
            }
          }
        ]
      }
      Transform {
        translation 0.656 -0.01 -0.203
        rotation 0 1 0 0
        children [
          Shape {
            appearance Appearance {
              material Material {
                diffuseColor 0.12549 0.290196 0.529412
              }
            }
            geometry Box {
              size 0.236 0.1 0.12
            }
          }
        ]
      }
      Transform {
        translation 0.128 -0.002 -0.09
        rotation 0 1 0 0
        children [
          Shape {
            appearance Appearance {
              material Material {
                diffuseColor 0.12549 0.290196 0.529412
              }
            }
            geometry Box {
              size 0.8 0.229 0.17
            }
          }
        ]
      }
      Transform {
        translation 0.5952 -0.002 -0.0782133
        rotation 0 1 0 0.785398
        children [
          Shape {
            appearance Appearance {
              material Material {
                diffuseColor 0.12549 0.290196 0.529412
              }
            }
            geometry Box {
              size 0.04 0.23 0.23
            }
          }
        ]
      }
    ]
  }
  physics Physics {
    density -1
    mass 92.31471578978483
    centerOfMass [
      0.09746903126202913 -0.005092782356006689 -0.11308759673171187
    ]
    inertiaMatrix [
      3.730004672444471 16.264203045927385 16.13964821340254
      0.02673265977304787 0.9533580534651469 -0.08064943487551691
    ]
  }
  linearVelocity 0.0025441724187080157 0.00023604293110968675 -0.00014878419787798565
  angularVelocity 0.00021011581584314654 -0.001465845282497656 -0.0015920457761443548
}
