#VRML_SIM R2023a utf8

EXTERNPROTO "https://raw.githubusercontent.com/cyberbotics/webots/R2023a/projects/objects/backgrounds/protos/TexturedBackground.proto"
EXTERNPROTO "https://raw.githubusercontent.com/cyberbotics/webots/R2023a/projects/objects/backgrounds/protos/TexturedBackgroundLight.proto"
EXTERNPROTO "https://raw.githubusercontent.com/cyberbotics/webots/R2023a/projects/objects/floors/protos/Floor.proto"

WorldInfo {
  basicTimeStep 16
  contactProperties [
    ContactProperties {
      material2 "dumbbell"
    }
  ]
}
Viewpoint {
  orientation -0.1627228519305623 -0.6518213239587081 0.7407092783895051 5.6330325234724645
  position -1.7884458364211506 1.3472849993690326 1.0875353738719058
}
TexturedBackground {
}
TexturedBackgroundLight {
}
Floor {
  size 5 5
}
Robot {
  translation 0.7343718268675893 0.42306945896499304 0.36560339621517757
  rotation -0.0011391921141768347 0.9922137661002074 0.12454133692300634 0.02767843013164583
  children [
    Solid {
      translation -0.24 -0.01 -0.4
      scale 0.001 0.001 0.001
      children [
        Shape {
          appearance Appearance {
            material Material {
              diffuseColor 0.933333 0.933333 0.92549
            }
          }
          geometry Mesh {
            url [
              "../stl/eje_trasero.stl"
            ]
          }
        }
      ]
      name "solid(2)"
    }
    Solid {
      translation 0.83 0 -0.35
      scale 0.001 0.001 0.001
      children [
        Shape {
          appearance Appearance {
            material Material {
              diffuseColor 0.933333 0.933333 0.92549
            }
          }
          geometry Mesh {
            url [
              "../stl/eje_delantero.stl"
            ]
          }
        }
      ]
      name "solid(1)"
    }
    DEF G0 Group {
      children [
        Transform {
          translation 0.84 -0.38 -0.2
          rotation 0 0 1 1.5708
          scale 0.38 0.38 0.4
          children [
            DEF RIGHT_STEER_HINGE2 Hinge2Joint {
              jointParameters HingeJointParameters {
                position 2.6804964035085186e-08
                axis 0 0 -1
                suspensionSpringConstant 200000
                suspensionDampingConstant 4000
                suspensionAxis 0 0 1
              }
              jointParameters2 JointParameters {
                position 3.176086435323751
                axis 1 0 0
                dampingConstant 5
              }
              device [
                RotationalMotor {
                  name "right_steer"
                  minPosition -0.45
                  maxPosition 0.45
                  maxTorque 10000
                  sound ""
                }
                PositionSensor {
                  name "right_steer_sensor"
                }
              ]
              device2 [
                RotationalMotor {
                  name "right_front_wheel"
                  acceleration 3.654970760233918
                  maxVelocity 131.57894736842104
                  maxTorque 0
                  sound ""
                }
                PositionSensor {
                  name "right_front_sensor"
                }
              ]
              endPoint Slot {
                type "vehicle wheel"
                endPoint Slot {
                  type "vehicle wheel"
                  endPoint Solid {
                    rotation 0.9999999999999994 -3.048587759777878e-08 1.157291495780381e-08 0.6158893743760528
                    children [
                      Transform {
                        translation 0.041 0 0
                        rotation 0 1 0 1.5708
                        children [
                          Shape {
                            appearance PBRAppearance {
                              baseColorMap ImageTexture {
                                url [
                                  "https://raw.githubusercontent.com/cyberbotics/webots/R2023a/projects/vehicles/protos/generic/textures/tractor_tire_tread_base_color.jpg"
                                ]
                              }
                              roughness 0.4
                              metalness 0
                              normalMap ImageTexture {
                                url [
                                  "https://raw.githubusercontent.com/cyberbotics/webots/R2023a/projects/vehicles/protos/generic/textures/tractor_tire_tread_normal.jpg"
                                ]
                              }
                              occlusionMap ImageTexture {
                                url [
                                  "https://raw.githubusercontent.com/cyberbotics/webots/R2023a/projects/vehicles/protos/generic/textures/tractor_tire_tread_occlusion.jpg"
                                ]
                              }
                              textureTransform TextureTransform {
                                rotation 1.5708
                                scale 1 7
                              }
                            }
                            geometry Cylinder {
                              bottom FALSE
                              height 0.19
                              radius 0.38
                              top FALSE
                              subdivision 24
                            }
                          }
                          Shape {
                            appearance PBRAppearance {
                              baseColorMap ImageTexture {
                                url [
                                  "https://raw.githubusercontent.com/cyberbotics/webots/R2023a/projects/vehicles/protos/generic/textures/tractor_front_tire_side_base_color.jpg"
                                ]
                              }
                              roughnessMap ImageTexture {
                                url [
                                  "https://raw.githubusercontent.com/cyberbotics/webots/R2023a/projects/vehicles/protos/generic/textures/tractor_front_tire_side_roughness.jpg"
                                ]
                              }
                              normalMap ImageTexture {
                                url [
                                  "https://raw.githubusercontent.com/cyberbotics/webots/R2023a/projects/vehicles/protos/generic/textures/tractor_front_tire_side_normal.jpg"
                                ]
                              }
                              occlusionMap ImageTexture {
                                url [
                                  "https://raw.githubusercontent.com/cyberbotics/webots/R2023a/projects/vehicles/protos/generic/textures/tractor_front_tire_side_occlusion.jpg"
                                ]
                              }
                            }
                            geometry Cylinder {
                              height 0.19
                              radius 0.38
                              side FALSE
                              subdivision 24
                            }
                          }
                        ]
                      }
                    ]
                    name "front right wheel"
                    model "tractor front wheel"
                    boundingObject Group {
                      children [
                        Transform {
                          translation 0.04 0 0
                          rotation 0 1 0 1.5708
                          children [
                            Cylinder {
                              height 0.19
                              radius 0.38
                              subdivision 24
                            }
                          ]
                        }
                      ]
                    }
                    physics Physics {
                      density -1
                      mass 30
                    }
                    linearVelocity 0.012009198210890925 2.4418750669346516e-05 0.00015901324067415715
                    angularVelocity -0.00020083862665970723 0.08314958173074682 8.226616187523413e-07
                  }
                }
              }
            }
          ]
        }
        Transform {
          translation 0.84 0.38 -0.2
          rotation 0 0 1 -1.5708
          scale 0.38 0.38 0.4
          children [
            DEF LEFT_STEER_HINGE2 Hinge2Joint {
              jointParameters HingeJointParameters {
                position 6.95960952795095e-08
                axis 0 0 -1
                suspensionSpringConstant 200000
                suspensionDampingConstant 4000
                suspensionAxis 0 0 1
              }
              jointParameters2 JointParameters {
                position 2.406836969451971
                axis -1 0 0
                dampingConstant 5
              }
              device [
                RotationalMotor {
                  name "left_steer"
                  minPosition -0.45
                  maxPosition 0.45
                  maxTorque 10000
                  sound ""
                }
                PositionSensor {
                  name "left_steer_sensor"
                }
              ]
              device2 [
                RotationalMotor {
                  name "left_front_wheel"
                  acceleration 3.654970760233918
                  maxVelocity 131.57894736842104
                  maxTorque 0
                  sound ""
                }
                PositionSensor {
                  name "left_front_sensor"
                }
                Brake {
                  name "left_front_brake"
                }
              ]
              endPoint Slot {
                type "vehicle wheel"
                endPoint Slot {
                  type "vehicle wheel"
                  endPoint Solid {
                    rotation -0.9999999999999946 4.3631510682939973e-08 -9.414663758742433e-08 0.5381987367632485
                    children [
                      Transform {
                        translation 0.041 0 0
                        rotation 0 -1 0 1.5708
                        children [
                          Shape {
                            appearance PBRAppearance {
                              baseColorMap ImageTexture {
                                url [
                                  "https://raw.githubusercontent.com/cyberbotics/webots/R2023a/projects/vehicles/protos/generic/textures/tractor_tire_tread_base_color.jpg"
                                ]
                              }
                              roughness 0.4
                              metalness 0
                              normalMap ImageTexture {
                                url [
                                  "https://raw.githubusercontent.com/cyberbotics/webots/R2023a/projects/vehicles/protos/generic/textures/tractor_tire_tread_normal.jpg"
                                ]
                              }
                              occlusionMap ImageTexture {
                                url [
                                  "https://raw.githubusercontent.com/cyberbotics/webots/R2023a/projects/vehicles/protos/generic/textures/tractor_tire_tread_occlusion.jpg"
                                ]
                              }
                              textureTransform TextureTransform {
                                rotation 1.5708
                                scale 1 7
                              }
                            }
                            geometry Cylinder {
                              bottom FALSE
                              height 0.19
                              radius 0.38
                              top FALSE
                              subdivision 24
                            }
                          }
                          Shape {
                            appearance PBRAppearance {
                              baseColorMap ImageTexture {
                                url [
                                  "https://raw.githubusercontent.com/cyberbotics/webots/R2023a/projects/vehicles/protos/generic/textures/tractor_front_tire_side_base_color.jpg"
                                ]
                              }
                              roughnessMap ImageTexture {
                                url [
                                  "https://raw.githubusercontent.com/cyberbotics/webots/R2023a/projects/vehicles/protos/generic/textures/tractor_front_tire_side_roughness.jpg"
                                ]
                              }
                              normalMap ImageTexture {
                                url [
                                  "https://raw.githubusercontent.com/cyberbotics/webots/R2023a/projects/vehicles/protos/generic/textures/tractor_front_tire_side_normal.jpg"
                                ]
                              }
                              occlusionMap ImageTexture {
                                url [
                                  "https://raw.githubusercontent.com/cyberbotics/webots/R2023a/projects/vehicles/protos/generic/textures/tractor_front_tire_side_occlusion.jpg"
                                ]
                              }
                            }
                            geometry Cylinder {
                              height 0.19
                              radius 0.38
                              side FALSE
                              subdivision 24
                            }
                          }
                        ]
                      }
                    ]
                    name "front left wheel"
                    model "tractor front wheel"
                    boundingObject Group {
                      children [
                        Transform {
                          translation 0.04 0 0
                          rotation 0 1 0 1.5708
                          children [
                            Cylinder {
                              height 0.19
                              radius 0.38
                              subdivision 24
                            }
                          ]
                        }
                      ]
                    }
                    physics Physics {
                      density -1
                      mass 30
                    }
                    linearVelocity 0.012008947532546384 2.4345319327685782e-05 0.00019858603879816314
                    angularVelocity -0.0002001053510368394 0.0831478467096477 5.269242231523662e-07
                  }
                }
              }
            }
          ]
        }
        Transform {
          translation -0.24 -0.4 -0.22
          rotation 0 0 1 1.5707996938995747
          scale 0.28 0.28 0.3
          children [
            DEF RIGHT_REAR_WHEEL_HINGE HingeJoint {
              jointParameters HingeJointParameters {
                position 1.8790394751264925
                dampingConstant 5
                suspensionSpringConstant 30000
                suspensionDampingConstant 2000
                suspensionAxis 0 0 1
              }
              device [
                RotationalMotor {
                  name "right_rear_wheel"
                  acceleration 2.314814814814815
                  maxVelocity 83.33333333333334
                  maxTorque 100000000
                  sound ""
                }
                PositionSensor {
                  name "right_rear_sensor"
                }
                Brake {
                  name "right_rear_brake"
                }
              ]
              endPoint Slot {
                type "vehicle wheel"
                endPoint Slot {
                  type "vehicle wheel"
                  endPoint Solid {
                    rotation 1 0 0 1.939204585548151
                    children [
                      Transform {
                        rotation 0 1 0 1.5708
                        children [
                          Shape {
                            appearance PBRAppearance {
                              baseColorMap ImageTexture {
                                url [
                                  "https://raw.githubusercontent.com/cyberbotics/webots/R2023a/projects/vehicles/protos/generic/textures/tractor_tire_tread_base_color.jpg"
                                ]
                              }
                              roughness 0.4
                              metalness 0
                              normalMap ImageTexture {
                                url [
                                  "https://raw.githubusercontent.com/cyberbotics/webots/R2023a/projects/vehicles/protos/generic/textures/tractor_tire_tread_normal.jpg"
                                ]
                              }
                              occlusionMap ImageTexture {
                                url [
                                  "https://raw.githubusercontent.com/cyberbotics/webots/R2023a/projects/vehicles/protos/generic/textures/tractor_tire_tread_occlusion.jpg"
                                ]
                              }
                              textureTransform TextureTransform {
                                rotation 1.5708
                                scale 1 7
                              }
                            }
                            geometry Cylinder {
                              bottom FALSE
                              height 0.37
                              radius 0.6
                              top FALSE
                              subdivision 24
                            }
                          }
                          Shape {
                            appearance PBRAppearance {
                              baseColorMap ImageTexture {
                                url [
                                  "https://raw.githubusercontent.com/cyberbotics/webots/R2023a/projects/vehicles/protos/generic/textures/tractor_rear_tire_side_base_color.jpg"
                                ]
                              }
                              roughnessMap ImageTexture {
                                url [
                                  "https://raw.githubusercontent.com/cyberbotics/webots/R2023a/projects/vehicles/protos/generic/textures/tractor_rear_tire_side_roughness.jpg"
                                ]
                              }
                              metalnessMap ImageTexture {
                                url [
                                  "https://raw.githubusercontent.com/cyberbotics/webots/R2023a/projects/vehicles/protos/generic/textures/tractor_rear_tire_side_metalness.jpg"
                                ]
                              }
                              normalMap ImageTexture {
                                url [
                                  "https://raw.githubusercontent.com/cyberbotics/webots/R2023a/projects/vehicles/protos/generic/textures/tractor_rear_tire_side_normal.jpg"
                                ]
                              }
                              occlusionMap ImageTexture {
                                url [
                                  "https://raw.githubusercontent.com/cyberbotics/webots/R2023a/projects/vehicles/protos/generic/textures/tractor_rear_tire_side_occlusion.jpg"
                                ]
                              }
                            }
                            geometry Cylinder {
                              height 0.37
                              radius 0.6
                              side FALSE
                              subdivision 24
                            }
                          }
                        ]
                      }
                    ]
                    name "rear right wheel"
                    model "tractor rear wheel"
                    boundingObject Group {
                      children [
                        Transform {
                          translation 0.04 0 0
                          rotation 0 1 0 1.5708
                          children [
                            Cylinder {
                              height 0.37
                              radius 0.6
                              subdivision 24
                            }
                          ]
                        }
                      ]
                    }
                    physics Physics {
                      density -1
                      mass 10
                    }
                    linearVelocity 0.01208660878396426 3.177930725774009e-05 -0.00012032589398704391
                    angularVelocity -0.0001606867012923958 0.07195887333078914 1.5286741872262395e-07
                  }
                }
              }
            }
          ]
        }
        Transform {
          translation -0.24 0.39 -0.22
          rotation 0 0 1 -1.5708
          scale 0.28 0.28 0.3
          children [
            DEF LEFT_REAR_WHEEL_HINGE HingeJoint {
              jointParameters HingeJointParameters {
                position 0.24793579197370108
                axis -1 0 0
                dampingConstant 5
                suspensionSpringConstant 30000
                suspensionDampingConstant 2000
                suspensionAxis 0 0 1
              }
              device [
                RotationalMotor {
                  name "left_rear_wheel"
                  acceleration 2.314814814814815
                  maxVelocity 83.33333333333334
                  maxTorque 100000000
                  sound ""
                }
                PositionSensor {
                  name "left_rear_sensor"
                }
                Brake {
                  name "left_rear_brake"
                }
              ]
              endPoint Slot {
                type "vehicle wheel"
                endPoint Slot {
                  type "vehicle wheel"
                  endPoint Solid {
                    rotation -1 0 0 0.2432788371704568
                    children [
                      Transform {
                        translation 0.041 0 0
                        rotation 0 -1 0 1.5708
                        children [
                          Shape {
                            appearance PBRAppearance {
                              baseColorMap ImageTexture {
                                url [
                                  "https://raw.githubusercontent.com/cyberbotics/webots/R2023a/projects/vehicles/protos/generic/textures/tractor_tire_tread_base_color.jpg"
                                ]
                              }
                              roughness 0.4
                              metalness 0
                              normalMap ImageTexture {
                                url [
                                  "https://raw.githubusercontent.com/cyberbotics/webots/R2023a/projects/vehicles/protos/generic/textures/tractor_tire_tread_normal.jpg"
                                ]
                              }
                              occlusionMap ImageTexture {
                                url [
                                  "https://raw.githubusercontent.com/cyberbotics/webots/R2023a/projects/vehicles/protos/generic/textures/tractor_tire_tread_occlusion.jpg"
                                ]
                              }
                              textureTransform TextureTransform {
                                rotation 1.5708
                                scale 1 7
                              }
                            }
                            geometry Cylinder {
                              bottom FALSE
                              height 0.37
                              radius 0.6
                              top FALSE
                              subdivision 24
                            }
                          }
                          Shape {
                            appearance PBRAppearance {
                              baseColorMap ImageTexture {
                                url [
                                  "https://raw.githubusercontent.com/cyberbotics/webots/R2023a/projects/vehicles/protos/generic/textures/tractor_rear_tire_side_base_color.jpg"
                                ]
                              }
                              roughnessMap ImageTexture {
                                url [
                                  "https://raw.githubusercontent.com/cyberbotics/webots/R2023a/projects/vehicles/protos/generic/textures/tractor_rear_tire_side_roughness.jpg"
                                ]
                              }
                              metalnessMap ImageTexture {
                                url [
                                  "https://raw.githubusercontent.com/cyberbotics/webots/R2023a/projects/vehicles/protos/generic/textures/tractor_rear_tire_side_metalness.jpg"
                                ]
                              }
                              normalMap ImageTexture {
                                url [
                                  "https://raw.githubusercontent.com/cyberbotics/webots/R2023a/projects/vehicles/protos/generic/textures/tractor_rear_tire_side_normal.jpg"
                                ]
                              }
                              occlusionMap ImageTexture {
                                url [
                                  "https://raw.githubusercontent.com/cyberbotics/webots/R2023a/projects/vehicles/protos/generic/textures/tractor_rear_tire_side_occlusion.jpg"
                                ]
                              }
                            }
                            geometry Cylinder {
                              height 0.37
                              radius 0.6
                              side FALSE
                              subdivision 24
                            }
                          }
                        ]
                      }
                    ]
                    name "rear left wheel"
                    model "tractor rear wheel"
                    boundingObject Group {
                      children [
                        Transform {
                          translation 0.04 0 0
                          rotation 0 1 0 1.5708
                          children [
                            Cylinder {
                              height 0.37
                              radius 0.6
                              subdivision 24
                            }
                          ]
                        }
                      ]
                    }
                    physics Physics {
                      density -1
                      mass 10
                    }
                    linearVelocity 0.012059297904149047 3.117419541760215e-05 -0.0001462698630110547
                    angularVelocity -0.0001602788121710137 0.07195021649525554 6.129746435608764e-07
                  }
                }
              }
            }
          ]
        }
        DEF base Solid {
          children [
            DEF G0 Group {
              children [
                Transform {
                  translation 0.5952 -0.002 -0.0782133
                  rotation 0 1 0 0.785398
                  children [
                    Shape {
                      appearance Appearance {
                        material Material {
                          diffuseColor 0.12549 0.290196 0.529412
                        }
                      }
                      geometry Box {
                        size 0.04 0.23 0.23
                      }
                    }
                  ]
                }
                Transform {
                  translation 0.128 -0.002 -0.09
                  rotation 0 1 0 0
                  children [
                    Shape {
                      appearance Appearance {
                        material Material {
                          diffuseColor 0.12549 0.290196 0.529412
                        }
                      }
                      geometry Box {
                        size 0.8 0.229 0.17
                      }
                    }
                  ]
                }
                Transform {
                  translation 0.656 -0.01 -0.203
                  rotation 0 1 0 0
                  children [
                    Shape {
                      appearance Appearance {
                        material Material {
                          diffuseColor 0.12549 0.290196 0.529412
                        }
                      }
                      geometry Box {
                        size 0.236 0.1 0.12
                      }
                    }
                  ]
                }
                Transform {
                  translation 0.831 -0.01 -0.2085
                  rotation 0 1 0 0
                  children [
                    Shape {
                      appearance Appearance {
                        material Material {
                          diffuseColor 0.12549 0.290196 0.529412
                        }
                      }
                      geometry Box {
                        size 0.119 0.5 0.13
                      }
                    }
                  ]
                }
                Transform {
                  translation 0.48 0.1873 0
                  rotation 0 0 1 -0.7854003061004253
                  children [
                    Shape {
                      appearance Appearance {
                        material Material {
                          diffuseColor 0.12549 0.290196 0.529412
                        }
                      }
                      geometry Box {
                        size 0.4 0.2 0.02
                      }
                    }
                  ]
                }
                Transform {
                  translation 0.48 -0.1885 0
                  rotation 0 0 1 0.7853996938995746
                  children [
                    Shape {
                      appearance Appearance {
                        material Material {
                          diffuseColor 0.12549 0.290196 0.529412
                        }
                      }
                      geometry Box {
                        size 0.4 0.2 0.02
                      }
                    }
                  ]
                }
                Transform {
                  translation 0.546 -0.001 0
                  rotation 0 0 1 1.5707996938995747
                  children [
                    Shape {
                      appearance Appearance {
                        material Material {
                          diffuseColor 0.12549 0.290196 0.529412
                        }
                      }
                      geometry Box {
                        size 0.24 0.29 0.02
                      }
                    }
                  ]
                }
                Transform {
                  translation -0.307 -0.01 -0.1569
                  children [
                    Shape {
                      appearance Appearance {
                        material Material {
                          diffuseColor 0.12549 0.290196 0.529412
                        }
                      }
                      geometry Box {
                        size 0.12 0.5 0.29
                      }
                    }
                  ]
                }
                Transform {
                  translation -0.25 -0.00999996 -0.22
                  rotation 1 0 0 1.5708
                  children [
                    Shape {
                      appearance Appearance {
                        material Material {
                          diffuseColor 0.12549 0.290196 0.529412
                        }
                      }
                      geometry Cylinder {
                        height 0.5
                        radius 0.08
                      }
                    }
                  ]
                }
                Transform {
                  translation 0.51 -0.01 -0.17
                  rotation 1 0 0 1.5708
                  children [
                    Shape {
                      appearance Appearance {
                        material Material {
                          diffuseColor 0.12549 0.290196 0.529412
                        }
                      }
                      geometry Cylinder {
                        height 0.1
                        radius 0.08
                      }
                    }
                  ]
                }
                Shape {
                  appearance Appearance {
                    material Material {
                      diffuseColor 0.12549 0.290196 0.529412
                    }
                  }
                  geometry Box {
                    size 0.82 0.8 0.022
                  }
                }
              ]
            }
          ]
          boundingObject USE G0
        }
      ]
    }
  ]
  boundingObject USE G0
  physics Physics {
    density -1
    mass 10
    centerOfMass [
      0.09746903126202917 -0.005092782356006689 -0.11308759673171191
    ]
    inertiaMatrix [
      3.7300046724444713 16.264203045927385 16.139648213402538
      0.02673265977304786 0.9533580534651473 -0.08064943487551691
    ]
  }
  linearVelocity 0.011798617356025947 1.931913618394704e-05 -0.0011047824641590082
  angularVelocity 9.40777347843167e-05 -0.0021129871603685676 -5.532227653521571e-07
}
