#VRML_SIM R2023a utf8

EXTERNPROTO "https://raw.githubusercontent.com/cyberbotics/webots/R2023a/projects/objects/backgrounds/protos/TexturedBackground.proto"
EXTERNPROTO "https://raw.githubusercontent.com/cyberbotics/webots/R2023a/projects/objects/backgrounds/protos/TexturedBackgroundLight.proto"
EXTERNPROTO "https://raw.githubusercontent.com/cyberbotics/webots/R2023a/projects/objects/floors/protos/Floor.proto"

WorldInfo {
  ERP 0.7
  basicTimeStep 16
  contactProperties [
    ContactProperties {
      material2 "dumbbell"
    }
  ]
}
Viewpoint {
  orientation 0.5435228059236165 -0.13502939204550976 -0.828462444969438 3.547559626356274
  position 2.051118647486423 0.2183318723817523 1.8558903227041177
}
TexturedBackground {
}
TexturedBackgroundLight {
}
Floor {
  size 5 5
}
Robot {
  translation 0.9524689123801376 0.8033492773887035 0.3721013120250982
  rotation 0.018596007671444006 0.07398260268600496 -0.9970861361981163 0.49128329837469237
  children [
    Solid {
      translation -0.24 -0.01 -0.42
      scale 0.001 0.001 0.001
      children [
        Shape {
          appearance Appearance {
            material Material {
              diffuseColor 0.933333 0.933333 0.92549
            }
          }
          geometry Mesh {
            url [
              "../stl/eje_trasero.stl"
            ]
          }
        }
      ]
      name "solid(2)"
    }
    Solid {
      translation 0.83 0 -0.35
      scale 0.001 0.001 0.001
      children [
        Shape {
          appearance Appearance {
            material Material {
              diffuseColor 0.933333 0.933333 0.92549
            }
          }
          geometry Mesh {
            url [
              "../stl/eje_delantero.stl"
            ]
          }
        }
      ]
      name "solid(1)"
    }
    DEF G0 Group {
      children [
        Transform {
          translation 0.84 -0.38 -0.2
          rotation 0 0 1 1.5708
          scale 0.38 0.38 0.4
          children [
            DEF RIGHT_STEER_HINGE2 Hinge2Joint {
              jointParameters HingeJointParameters {
                position -3.959658490572393e-07
                axis 0 0 -1
                suspensionAxis 0 0 1
              }
              jointParameters2 JointParameters {
                position 20.705240243669007
                axis 1 0 0
                dampingConstant 5
              }
              device [
                RotationalMotor {
                  name "right_steer"
                  minPosition -0.45
                  maxPosition 0.45
                  maxTorque 10000
                  sound ""
                }
                PositionSensor {
                  name "right_steer_sensor"
                }
              ]
              device2 [
                RotationalMotor {
                  name "right_front_wheel"
                  acceleration 3.654970760233918
                  maxVelocity 131.57894736842104
                  maxTorque 0
                  sound ""
                }
                PositionSensor {
                  name "right_front_sensor"
                }
              ]
              endPoint Slot {
                type "vehicle wheel"
                endPoint Slot {
                  type "vehicle wheel"
                  endPoint Solid {
                    rotation -0.9999999999912166 -4.1525266215592144e-07 -4.170649218038969e-06 0.009248764548870922
                    children [
                      Transform {
                        translation 0.041 0 0
                        rotation 0 1 0 1.5708
                        children [
                          Shape {
                            appearance PBRAppearance {
                              baseColorMap ImageTexture {
                                url [
                                  "https://raw.githubusercontent.com/cyberbotics/webots/R2023a/projects/vehicles/protos/generic/textures/tractor_tire_tread_base_color.jpg"
                                ]
                              }
                              roughness 0.4
                              metalness 0
                              normalMap ImageTexture {
                                url [
                                  "https://raw.githubusercontent.com/cyberbotics/webots/R2023a/projects/vehicles/protos/generic/textures/tractor_tire_tread_normal.jpg"
                                ]
                              }
                              occlusionMap ImageTexture {
                                url [
                                  "https://raw.githubusercontent.com/cyberbotics/webots/R2023a/projects/vehicles/protos/generic/textures/tractor_tire_tread_occlusion.jpg"
                                ]
                              }
                              textureTransform TextureTransform {
                                rotation 1.5708
                                scale 1 7
                              }
                            }
                            geometry Cylinder {
                              bottom FALSE
                              height 0.19
                              radius 0.38
                              top FALSE
                              subdivision 24
                            }
                          }
                          Shape {
                            appearance PBRAppearance {
                              baseColorMap ImageTexture {
                                url [
                                  "https://raw.githubusercontent.com/cyberbotics/webots/R2023a/projects/vehicles/protos/generic/textures/tractor_front_tire_side_base_color.jpg"
                                ]
                              }
                              roughnessMap ImageTexture {
                                url [
                                  "https://raw.githubusercontent.com/cyberbotics/webots/R2023a/projects/vehicles/protos/generic/textures/tractor_front_tire_side_roughness.jpg"
                                ]
                              }
                              normalMap ImageTexture {
                                url [
                                  "https://raw.githubusercontent.com/cyberbotics/webots/R2023a/projects/vehicles/protos/generic/textures/tractor_front_tire_side_normal.jpg"
                                ]
                              }
                              occlusionMap ImageTexture {
                                url [
                                  "https://raw.githubusercontent.com/cyberbotics/webots/R2023a/projects/vehicles/protos/generic/textures/tractor_front_tire_side_occlusion.jpg"
                                ]
                              }
                            }
                            geometry Cylinder {
                              height 0.19
                              radius 0.38
                              side FALSE
                              subdivision 24
                            }
                          }
                        ]
                      }
                    ]
                    name "front right wheel"
                    model "tractor front wheel"
                    boundingObject Group {
                      children [
                        Transform {
                          translation 0.04 0 0
                          rotation 0 1 0 1.5708
                          children [
                            Cylinder {
                              height 0.19
                              radius 0.38
                              subdivision 24
                            }
                          ]
                        }
                      ]
                    }
                    physics Physics {
                      density -1
                      mass 10
                    }
                  }
                }
              }
            }
          ]
        }
        Transform {
          translation 0.84 0.37 -0.2
          rotation 0 0 1 -1.5708
          scale 0.38 0.38 0.4
          children [
            DEF LEFT_STEER_HINGE2 Hinge2Joint {
              jointParameters HingeJointParameters {
                position 6.257470269129591e-07
                axis 0 0 -1
                suspensionAxis 0 0 1
              }
              jointParameters2 JointParameters {
                position 22.908879452660805
                axis -1 0 0
                dampingConstant 5
              }
              device [
                RotationalMotor {
                  name "left_steer"
                  minPosition -0.45
                  maxPosition 0.45
                  maxTorque 10000
                  sound ""
                }
                PositionSensor {
                  name "left_steer_sensor"
                }
              ]
              device2 [
                RotationalMotor {
                  name "left_front_wheel"
                  acceleration 3.654970760233918
                  maxVelocity 131.57894736842104
                  maxTorque 0
                  sound ""
                }
                PositionSensor {
                  name "left_front_sensor"
                }
                Brake {
                  name "left_front_brake"
                }
              ]
              endPoint Slot {
                type "vehicle wheel"
                endPoint Slot {
                  type "vehicle wheel"
                  endPoint Solid {
                    rotation -0.999999999971488 4.854837978556567e-07 -7.535787298648371e-06 0.037221601141396186
                    children [
                      Transform {
                        translation 0.041 0 0
                        rotation 0 -1 0 1.5708
                        children [
                          Shape {
                            appearance PBRAppearance {
                              baseColorMap ImageTexture {
                                url [
                                  "https://raw.githubusercontent.com/cyberbotics/webots/R2023a/projects/vehicles/protos/generic/textures/tractor_tire_tread_base_color.jpg"
                                ]
                              }
                              roughness 0.4
                              metalness 0
                              normalMap ImageTexture {
                                url [
                                  "https://raw.githubusercontent.com/cyberbotics/webots/R2023a/projects/vehicles/protos/generic/textures/tractor_tire_tread_normal.jpg"
                                ]
                              }
                              occlusionMap ImageTexture {
                                url [
                                  "https://raw.githubusercontent.com/cyberbotics/webots/R2023a/projects/vehicles/protos/generic/textures/tractor_tire_tread_occlusion.jpg"
                                ]
                              }
                              textureTransform TextureTransform {
                                rotation 1.5708
                                scale 1 7
                              }
                            }
                            geometry Cylinder {
                              bottom FALSE
                              height 0.19
                              radius 0.38
                              top FALSE
                              subdivision 24
                            }
                          }
                          Shape {
                            appearance PBRAppearance {
                              baseColorMap ImageTexture {
                                url [
                                  "https://raw.githubusercontent.com/cyberbotics/webots/R2023a/projects/vehicles/protos/generic/textures/tractor_front_tire_side_base_color.jpg"
                                ]
                              }
                              roughnessMap ImageTexture {
                                url [
                                  "https://raw.githubusercontent.com/cyberbotics/webots/R2023a/projects/vehicles/protos/generic/textures/tractor_front_tire_side_roughness.jpg"
                                ]
                              }
                              normalMap ImageTexture {
                                url [
                                  "https://raw.githubusercontent.com/cyberbotics/webots/R2023a/projects/vehicles/protos/generic/textures/tractor_front_tire_side_normal.jpg"
                                ]
                              }
                              occlusionMap ImageTexture {
                                url [
                                  "https://raw.githubusercontent.com/cyberbotics/webots/R2023a/projects/vehicles/protos/generic/textures/tractor_front_tire_side_occlusion.jpg"
                                ]
                              }
                            }
                            geometry Cylinder {
                              height 0.19
                              radius 0.38
                              side FALSE
                              subdivision 24
                            }
                          }
                        ]
                      }
                    ]
                    name "front left wheel"
                    model "tractor front wheel"
                    boundingObject Group {
                      children [
                        Transform {
                          translation 0.04 0 0
                          rotation 0 1 0 1.5708
                          children [
                            Cylinder {
                              height 0.19
                              radius 0.38
                              subdivision 24
                            }
                          ]
                        }
                      ]
                    }
                    physics Physics {
                      density -1
                      mass 10
                    }
                  }
                }
              }
            }
          ]
        }
        Transform {
          translation -0.24 -0.4 -0.22
          rotation 0 0 1 1.5707996938995747
          scale 0.28 0.28 0.3
          children [
            DEF RIGHT_REAR_WHEEL_HINGE HingeJoint {
              jointParameters HingeJointParameters {
                position 2.0084845212944473
                dampingConstant 5
                suspensionAxis 0 0 1
              }
              device [
                RotationalMotor {
                  name "right_rear_wheel"
                  acceleration 2.314814814814815
                  maxVelocity 83.33333333333334
                  maxTorque 100000000
                  sound ""
                }
                PositionSensor {
                  name "right_rear_sensor"
                }
                Brake {
                  name "right_rear_brake"
                }
              ]
              endPoint Slot {
                type "vehicle wheel"
                endPoint Slot {
                  type "vehicle wheel"
                  endPoint Solid {
                    rotation -1 0 0 0.003664843167257492
                    children [
                      Transform {
                        translation 0.05 0 0
                        rotation 0 1 0 1.5708
                        children [
                          Shape {
                            appearance PBRAppearance {
                              baseColorMap ImageTexture {
                                url [
                                  "https://raw.githubusercontent.com/cyberbotics/webots/R2023a/projects/vehicles/protos/generic/textures/tractor_tire_tread_base_color.jpg"
                                ]
                              }
                              roughness 0.4
                              metalness 0
                              normalMap ImageTexture {
                                url [
                                  "https://raw.githubusercontent.com/cyberbotics/webots/R2023a/projects/vehicles/protos/generic/textures/tractor_tire_tread_normal.jpg"
                                ]
                              }
                              occlusionMap ImageTexture {
                                url [
                                  "https://raw.githubusercontent.com/cyberbotics/webots/R2023a/projects/vehicles/protos/generic/textures/tractor_tire_tread_occlusion.jpg"
                                ]
                              }
                              textureTransform TextureTransform {
                                rotation 1.5708
                                scale 1 7
                              }
                            }
                            geometry Cylinder {
                              bottom FALSE
                              height 0.37
                              radius 0.6
                              top FALSE
                              subdivision 24
                            }
                          }
                          Shape {
                            appearance PBRAppearance {
                              baseColorMap ImageTexture {
                                url [
                                  "https://raw.githubusercontent.com/cyberbotics/webots/R2023a/projects/vehicles/protos/generic/textures/tractor_rear_tire_side_base_color.jpg"
                                ]
                              }
                              roughnessMap ImageTexture {
                                url [
                                  "https://raw.githubusercontent.com/cyberbotics/webots/R2023a/projects/vehicles/protos/generic/textures/tractor_rear_tire_side_roughness.jpg"
                                ]
                              }
                              metalnessMap ImageTexture {
                                url [
                                  "https://raw.githubusercontent.com/cyberbotics/webots/R2023a/projects/vehicles/protos/generic/textures/tractor_rear_tire_side_metalness.jpg"
                                ]
                              }
                              normalMap ImageTexture {
                                url [
                                  "https://raw.githubusercontent.com/cyberbotics/webots/R2023a/projects/vehicles/protos/generic/textures/tractor_rear_tire_side_normal.jpg"
                                ]
                              }
                              occlusionMap ImageTexture {
                                url [
                                  "https://raw.githubusercontent.com/cyberbotics/webots/R2023a/projects/vehicles/protos/generic/textures/tractor_rear_tire_side_occlusion.jpg"
                                ]
                              }
                            }
                            geometry Cylinder {
                              height 0.37
                              radius 0.6
                              side FALSE
                              subdivision 24
                            }
                          }
                        ]
                      }
                    ]
                    name "rear right wheel"
                    model "tractor rear wheel"
                    boundingObject Group {
                      children [
                        Transform {
                          translation 0.04 0 0
                          rotation 0 1 0 1.5708
                          children [
                            Cylinder {
                              height 0.37
                              radius 0.6
                              subdivision 24
                            }
                          ]
                        }
                      ]
                    }
                    physics Physics {
                      density -1
                      mass 10
                    }
                  }
                }
              }
            }
          ]
        }
        Transform {
          translation -0.24 0.39 -0.22
          rotation 0 0 1 -1.5708
          scale 0.28 0.28 0.3
          children [
            DEF LEFT_REAR_WHEEL_HINGE HingeJoint {
              jointParameters HingeJointParameters {
                position 9.01043406453063
                axis -1 0 0
                dampingConstant 5
                suspensionAxis 0 0 1
              }
              device [
                RotationalMotor {
                  name "left_rear_wheel"
                  acceleration 2.314814814814815
                  maxVelocity 83.33333333333334
                  maxTorque 100000000
                  sound ""
                }
                PositionSensor {
                  name "left_rear_sensor"
                }
                Brake {
                  name "left_rear_brake"
                }
              ]
              endPoint Slot {
                type "vehicle wheel"
                endPoint Slot {
                  type "vehicle wheel"
                  endPoint Solid {
                    rotation 1 0 0 0.017708326160819892
                    children [
                      Transform {
                        translation 0.05 0 0
                        rotation 0 -1 0 1.5708
                        children [
                          Shape {
                            appearance PBRAppearance {
                              baseColorMap ImageTexture {
                                url [
                                  "https://raw.githubusercontent.com/cyberbotics/webots/R2023a/projects/vehicles/protos/generic/textures/tractor_tire_tread_base_color.jpg"
                                ]
                              }
                              roughness 0.4
                              metalness 0
                              normalMap ImageTexture {
                                url [
                                  "https://raw.githubusercontent.com/cyberbotics/webots/R2023a/projects/vehicles/protos/generic/textures/tractor_tire_tread_normal.jpg"
                                ]
                              }
                              occlusionMap ImageTexture {
                                url [
                                  "https://raw.githubusercontent.com/cyberbotics/webots/R2023a/projects/vehicles/protos/generic/textures/tractor_tire_tread_occlusion.jpg"
                                ]
                              }
                              textureTransform TextureTransform {
                                rotation 1.5708
                                scale 1 7
                              }
                            }
                            geometry Cylinder {
                              bottom FALSE
                              height 0.37
                              radius 0.6
                              top FALSE
                              subdivision 24
                            }
                          }
                          Shape {
                            appearance PBRAppearance {
                              baseColorMap ImageTexture {
                                url [
                                  "https://raw.githubusercontent.com/cyberbotics/webots/R2023a/projects/vehicles/protos/generic/textures/tractor_rear_tire_side_base_color.jpg"
                                ]
                              }
                              roughnessMap ImageTexture {
                                url [
                                  "https://raw.githubusercontent.com/cyberbotics/webots/R2023a/projects/vehicles/protos/generic/textures/tractor_rear_tire_side_roughness.jpg"
                                ]
                              }
                              metalnessMap ImageTexture {
                                url [
                                  "https://raw.githubusercontent.com/cyberbotics/webots/R2023a/projects/vehicles/protos/generic/textures/tractor_rear_tire_side_metalness.jpg"
                                ]
                              }
                              normalMap ImageTexture {
                                url [
                                  "https://raw.githubusercontent.com/cyberbotics/webots/R2023a/projects/vehicles/protos/generic/textures/tractor_rear_tire_side_normal.jpg"
                                ]
                              }
                              occlusionMap ImageTexture {
                                url [
                                  "https://raw.githubusercontent.com/cyberbotics/webots/R2023a/projects/vehicles/protos/generic/textures/tractor_rear_tire_side_occlusion.jpg"
                                ]
                              }
                            }
                            geometry Cylinder {
                              height 0.37
                              radius 0.6
                              side FALSE
                              subdivision 24
                            }
                          }
                        ]
                      }
                    ]
                    name "rear left wheel"
                    model "tractor rear wheel"
                    boundingObject Group {
                      children [
                        Transform {
                          translation 0.04 0 0
                          rotation 0 1 0 1.5708
                          children [
                            Cylinder {
                              height 0.37
                              radius 0.6
                              subdivision 24
                            }
                          ]
                        }
                      ]
                    }
                    physics Physics {
                      density -1
                      mass 10
                    }
                  }
                }
              }
            }
          ]
        }
        DEF base Solid {
          children [
            DEF G0 Group {
              children [
                Transform {
                  translation 0.5952 -0.002 -0.0782133
                  rotation 0 1 0 0.785398
                  children [
                    Shape {
                      appearance Appearance {
                        material Material {
                          diffuseColor 0.12549 0.290196 0.529412
                        }
                      }
                      geometry Box {
                        size 0.04 0.23 0.23
                      }
                    }
                  ]
                }
                Transform {
                  translation 0.128 -0.002 -0.09
                  rotation 0 1 0 0
                  children [
                    Shape {
                      appearance Appearance {
                        material Material {
                          diffuseColor 0.12549 0.290196 0.529412
                        }
                      }
                      geometry Box {
                        size 0.8 0.229 0.17
                      }
                    }
                  ]
                }
                Transform {
                  translation 0.656 -0.01 -0.203
                  rotation 0 1 0 0
                  children [
                    Shape {
                      appearance Appearance {
                        material Material {
                          diffuseColor 0.12549 0.290196 0.529412
                        }
                      }
                      geometry Box {
                        size 0.236 0.1 0.12
                      }
                    }
                  ]
                }
                Transform {
                  translation 0.831 -0.01 -0.2085
                  rotation 0 1 0 0
                  children [
                    Shape {
                      appearance Appearance {
                        material Material {
                          diffuseColor 0.12549 0.290196 0.529412
                        }
                      }
                      geometry Box {
                        size 0.119 0.5 0.13
                      }
                    }
                  ]
                }
                Transform {
                  translation 0.48 0.1873 0
                  rotation 0 0 1 -0.7854003061004253
                  children [
                    Shape {
                      appearance Appearance {
                        material Material {
                          diffuseColor 0.12549 0.290196 0.529412
                        }
                      }
                      geometry Box {
                        size 0.4 0.2 0.02
                      }
                    }
                  ]
                }
                Transform {
                  translation 0.48 -0.1885 0
                  rotation 0 0 1 0.7853996938995746
                  children [
                    Shape {
                      appearance Appearance {
                        material Material {
                          diffuseColor 0.12549 0.290196 0.529412
                        }
                      }
                      geometry Box {
                        size 0.4 0.2 0.02
                      }
                    }
                  ]
                }
                Transform {
                  translation 0.546 -0.001 0
                  rotation 0 0 1 1.5707996938995747
                  children [
                    Shape {
                      appearance Appearance {
                        material Material {
                          diffuseColor 0.12549 0.290196 0.529412
                        }
                      }
                      geometry Box {
                        size 0.24 0.29 0.02
                      }
                    }
                  ]
                }
                Transform {
                  translation -0.307 -0.01 -0.1569
                  children [
                    Shape {
                      appearance Appearance {
                        material Material {
                          diffuseColor 0.12549 0.290196 0.529412
                        }
                      }
                      geometry Box {
                        size 0.12 0.5 0.29
                      }
                    }
                  ]
                }
                Transform {
                  translation -0.25 -0.00999996 -0.22
                  rotation 1 0 0 1.5708
                  children [
                    Shape {
                      appearance Appearance {
                        material Material {
                          diffuseColor 0.12549 0.290196 0.529412
                        }
                      }
                      geometry Cylinder {
                        height 0.5
                        radius 0.08
                      }
                    }
                  ]
                }
                Transform {
                  translation 0.51 -0.01 -0.17
                  rotation 1 0 0 1.5708
                  children [
                    Shape {
                      appearance Appearance {
                        material Material {
                          diffuseColor 0.12549 0.290196 0.529412
                        }
                      }
                      geometry Cylinder {
                        height 0.1
                        radius 0.08
                      }
                    }
                  ]
                }
                Shape {
                  appearance Appearance {
                    material Material {
                      diffuseColor 0.12549 0.290196 0.529412
                    }
                  }
                  geometry Box {
                    size 0.82 0.8 0.022
                  }
                }
              ]
            }
          ]
          boundingObject USE G0
        }
      ]
    }
  ]
  boundingObject USE G0
  physics Physics {
    density -1
    mass 50
    centerOfMass [
      0.09746903126202917 -0.005092782356006689 -0.11308759673171191
    ]
    inertiaMatrix [
      3.7300046724444713 16.264203045927385 16.139648213402538
      0.02673265977304786 0.9533580534651473 -0.08064943487551691
    ]
  }
  rotationStep 0.01
  linearVelocity 0.0015506731542153194 -0.0015341540464055335 -5.803509894949457e-05
  angularVelocity -0.00023242764995034566 -0.0002995982174305007 0.0015356217781565332
}
